<?xml version="1.0"?>
<robot name="chico_mendes">

    <material name="white">
        <color rgba="0.9 0.9 0.9 1"/>
    </material>

    <material name="green">
        <color rgba="0.0 0.5 0.0 1"/>
    </material>

    <material name="grey">
        <color rgba="0.7 0.7 0.7 1"/>
    </material>


    <link name="base_footprint" />


    <link name="base_link">
        <visual>
            <geometry>   
                <box size="0.6 0.4 0.2"/>
            </geometry>
            <origin xyz="0.0 0.0 0.1" rpy="0.0 0.0 0.0"/>
            <material name="green" />
        </visual>  
        <collision>
            <geometry>
                <box size="0.6 0.4 0.2"/>
            </geometry>    
        </collision>
        <inertial>
            <mass value="10.0"/>
            <inertia ixx="0.0" ixy="0.0" ixz="0.0" iyy="0.0" iyz="0.0" izz="0.0"/>
        </inertial>
    </link>

    <link name="lidar">
        <visual>
            <geometry>
                <cylinder radius="0.1" length="0.05"/>
            </geometry>
            <origin xyz="0.0 0.0 0.0" rpy="0.0 0.0 0.0"/>
            <material name="white" />
        </visual>
    </link>

    <link name="rear_left_wheel">
        <visual>
            <geometry>
                <cylinder radius="0.1" length="0.05"/>
            </geometry>
            <origin xyz="0.0 0.0 0.0" rpy="1.57 0.0 0.0"/>
            <material name="grey" />
        </visual>        
    </link>

    <link name="front_leaf_wheel">
        <visual>
            <geometry>
                <cylinder radius="0.1" length="0.05"/>
            </geometry>
            <origin xyz="0.0 0.0 0.0" rpy="1.57 0.0 0.0"/>
            <material name="grey" />
        </visual>
    </link>

    <link name="rear_right_wheel">
        <visual>
            <geometry>
                <cylinder radius="0.1" length="0.05"/>
            </geometry>
            <origin xyz="0.0 0.0 0.0" rpy="1.57 0.0 0.0"/>
            <material name="grey" />
        </visual>        
    </link>

    <link name="front_right_wheel">
        <visual>
            <geometry>
                <cylinder radius="0.1" length="0.05"/>
            </geometry>
            <origin xyz="0.0 0.0 0.0" rpy="1.57 0.0 0.0"/>
            <material name="grey" />
        </visual>        
    </link>

    <joint name="base_joint" type="fixed">
        <parent link="base_footprint"/>
        <child link="base_link"/>
        <origin xyz="0.0 0.0 0.1" rpy="0.0 0.0 0.0"/>
                
    </joint>

    <joint name="base_lidar_joint" type="fixed">
        <parent link="base_link"/>
        <child link="lidar"/>
        <origin xyz="0.0 0.0 0.225" rpy="0.0 0.0 0.0"/>        
    </joint>

    <joint name="base_r_left_wheel_joint" type="continuous">
        <parent link="base_link"/>
        <child link="rear_left_wheel"/>
        <origin xyz="-0.15 0.225 0.0" rpy="0.0 0.0 0.0"/>
        <axis xyz="0.0 1.0 0.0"/>
    </joint>

    <joint name="base_f_leaft_wheel_joint" type="continuous">
        <parent link="base_link"/>  
        <child link="front_leaf_wheel"/>
        <origin xyz="0.15 0.225 0.0" rpy="0.0 0.0 0.0"/>
        <axis xyz="0.0 1.0 0.0"/>
    </joint>

    <joint name="base_r_rigth_wheel_joint" type="continuous">
        <parent link="base_link"/>
        <child link="rear_right_wheel"/>
        <origin xyz="-0.15 -0.225 0.0" rpy="0.0 0.0 0.0"/>
        <axis xyz="0.0 1.0 0.0"/>
    </joint>

    <joint name="base_f_rigth_wheel_joint" type="continuous">
        <parent link="base_link"/>
        <child link="front_right_wheel"/>
        <origin xyz="0.15 -0.225 0.0" rpy="0.0 0.0 0.0"/>
        <axis xyz="0.0 1.0 0.0"/>
    </joint>


</robot>
